Workbook

Sheet 09_DanhMuc
A1: DANH MỤC DÙNG CHO DROPDOWN — KHÔNG CẦN CHỈNH SỬA
A2: Trạng thái | B2: Vai trò công việc | C2: Độ khó | D2: Điểm 1–5 | E2: Có/Không | F2: Loại minh chứng | G2: Nhóm nội dung | H2: Mức độ yêu cầu | I2: Kết quả kiểm tra | J2: Loại thành viên
A3: Chưa làm | B3: Chính | C3: 1 | D3: 1 | E3: Có | F3: Commit | G3: Blueprint | H3: Bắt buộc | I3: Đạt | J3: Khán giả
A4: Đang làm | B4: Phối hợp | C4: 2 | D4: 2 | E4: Không | F4: Pull request | G4: Cài đặt | H4: Chọn ít nhất 2 luồng | I4: Chưa đạt | J4: Ban tổ chức
A5: Hoàn thành | B5: Hỗ trợ | C5: 3 | D5: 3 | F5: Source code | G5: Kiểm thử | H5: Khuyến nghị | I5: Chưa kiểm tra | J5: Nhân sự soát vé
A6: Không áp dụng | C6: 4 | D6: 4 | F6: Sơ đồ | G6: Nộp bài | I6: Không áp dụng
C7: 5 | D7: 5 | F7: Tài liệu | G7: Vấn đáp
F8: Test report
F9: Ảnh chụp
F10: Video demo
F11: Google Drive
F12: Khác

Sheet 00_HuongDan
A1: HƯỚNG DẪN ĐIỀN FILE TỰ ĐÁNH GIÁ ĐỒ ÁN TICKETBOX
A3: Mục đích: Nhóm sinh viên tự khai báo đầy đủ phần việc, minh chứng và mức độ đóng góp. Giảng viên dùng file này để kiểm tra và vấn đáp; nội dung khai báo phải khớp với source code, Blueprint và video.
A5: Bước | B5: Sheet cần điền | C5: Sinh viên thực hiện | D5: Yêu cầu tối thiểu
A6: 1 | B6: 01_ThongTinNhom | C6: Điền thông tin nhóm, 1–4 thành viên và các link nộp bài. | D6: Link Google Drive phải public và mở được.
A7: 2 | B7: 02_ChecklistYeuCau | C7: Đối chiếu từng yêu cầu TicketBox; chọn owner, trạng thái, % hoàn thành và dán minh chứng. | D7: Không ghi “đã làm” nếu không có link/path minh chứng.
A8: 3 | B8: 03_PhanCongTask | C8: Tách công việc đủ nhỏ để phân biệt đóng góp cá nhân. | D8: Mỗi task phải có sản phẩm đầu ra và tiêu chí hoàn thành.
A9: 4 | B9: 04_TuDanhGia | C9: Mỗi thành viên tự chấm 1–5 và mô tả 3 đóng góp quan trọng nhất. | D9: Không tự chấm 5 nếu không thể giải thích khi vấn đáp.
A10: 5 | B10: 05_DanhGiaCheo | C10: Các thành viên đánh giá chéo, nêu lý do và ví dụ cụ thể. | D10: Nhóm 1 người để trống sheet này.
A11: 6 | B11: 06_MinhChung_NopBai | C11: Liệt kê commit/PR/tài liệu/sơ đồ/test/video và kiểm tra cấu trúc Google Drive. | D11: Mỗi minh chứng phải có người thực hiện và cách kiểm tra.
A12: 7 | B12: 07_ChuanBiVanDap | C12: Phân công thành viên chuẩn bị giải thích các quyết định kiến trúc và cơ chế kỹ thuật. | D12: Người phụ trách phải hiểu code, không chỉ đọc slide.
A13: 8 | B13: 08_TongHopGV | C13: Xem % tiến độ toàn nhóm, % hoàn thành đủ minh chứng và cảnh báo đóng góp cá nhân. | D13: Ưu tiên chỉ số “Hoàn thành đủ minh chứng”; các mục Không áp dụng không tính vào mẫu số.
A15: QUY ƯỚC MÀU
A16: Màu vàng | B16: Ô sinh viên cần điền
A17: Màu xám | B17: Ô công thức/tổng hợp — không sửa
A18: Màu xanh lá | B18: Thông tin hướng dẫn hoặc mục đã đạt
A19: Màu đỏ nhạt | B19: Thông tin bắt buộc/cảnh báo
A21: NGUỒN ĐẶC TẢ
A22: Đặc tả TicketBox | B22: https://nndkhoa.github.io/software-design-docs/exercises/project/spec-ticketbox.html
A23: Lưu ý | B23: File đánh giá này diễn giải yêu cầu để sinh viên tự khai báo; không thay thế đặc tả chính thức.

Sheet 01_ThongTinNhom
A1: THÔNG TIN NHÓM VÀ LINK NỘP BÀI
A3: A. THÔNG TIN CHUNG
A4: Mã nhóm * | C4: Lớp * | D4: CQ2023/31 | E4: Tên đồ án | F4: TicketBox | G4: Ngày cập nhật | H4: 46215.329
A5: Tên nhóm | C5: Số thành viên | D5: =COUNTIFS(B16:B19,"<>",G16:G19,"Có") -> 4 | E5: Link repository * | G5: Nhánh/Tag nộp
A6: Link Google Drive public * | E6: Link Blueprint
A7: Link thư mục source/src | E7: Link thư mục clips/video
A8: Link demo đang chạy (nếu có) | E8: Link tài liệu khác
A10: Link Google Drive phải bật quyền “Anyone with the link/Người có đường liên kết — Viewer”. Thư mục phải có đủ: (1) blueprint.pdf hoặc blueprint/, (2) src/ + data/ + README.md, (3) clips/ chứa video MP4 có camera thành viên và demo trực tiếp.
A14: B. DANH SÁCH THÀNH VIÊN — CHỈ ĐIỀN ĐÚNG SỐ NGƯỜI THỰC TẾ (1–4)
A15: STT | B15: Họ và tên * | C15: MSSV * | D15: Email | E15: Vai trò chính | F15: GitHub username | G15: Tham gia nhóm? | H15: Ghi chú
A16: 1 | B16: Nguyễn Minh Tú | C16: 23120101 | D16: 23120101@student.hcmus.edu.vn | E16: Mobile/Check-in | F16: PeriodicallyZoneOut | G16: Có
A17: 2 | B17: Võ Hoàng Danh | C17: 23120117 | D17: 23120117@student.hcmus.edu.vn | E17: Testing/Tài liệu | F17: HoangDanhVo | G17: Có
A18: 3 | B18: Nguyễn Hữu Phúc | C18: 23120157 | D18: 23120157@student.hcmus.edu.vn | E18: Backend | F18: Nhp125 | G18: Có
A19: 4 | B19: Huỳnh Thái Toàn | C19: 23120175 | D19: 23120175@student.hcmus.edu.vn | E19: Kiến trúc/Blueprint | F19: Toanapr | G19: Có
A21: C. XÁC NHẬN CỦA NHÓM
A22: Cam kết | B22: Nhóm xác nhận các thông tin, link và tỷ lệ đóng góp trong file là đúng; mỗi thành viên có thể giải thích phần việc đã khai báo.
A23: Người đại diện | C23: Ngày xác nhận | E23: Trạng thái link Drive | F23: Mở được | G23: Đã kiểm tra trên thiết bị khác? | H23: Có
A24: Ghi chú

Sheet 02_ChecklistYeuCau
A1: CHECKLIST ĐỐI CHIẾU YÊU CẦU ĐỒ ÁN TICKETBOX
A3: Điền theo sản phẩm thực tế. “Tiến độ tự khai” là trung bình cột % HT. “Hoàn thành đủ minh chứng” chỉ tính mục có trạng thái Hoàn thành, tự kiểm tra Đạt và có link/path minh chứng. Mục “Không áp dụng” được loại khỏi mẫu số.
A4: TIẾN ĐỘ TỰ KHAI | B4: =IFERROR(SUMIFS($H$6:$H$43,$G$6:$G$43,"<>Không áp dụng")/(COUNTIFS($A$6:$A$43,"<>",$G$6:$G$43,"<>Không áp dụng"))/100,0) -> 0.85789474 | C4: HOÀN THÀNH 100% | D4: =IFERROR(COUNTIFS($G$6:$G$43,"Hoàn thành")/(COUNTIFS($A$6:$A$43,"<>",$G$6:$G$43,"<>Không áp dụng")),0) -> 0.68421053 | E4: TỰ KIỂM TRA ĐẠT | F4: =IFERROR(COUNTIFS($J$6:$J$43,"Đạt",$G$6:$G$43,"<>Không áp dụng")/(COUNTIFS($A$6:$A$43,"<>",$G$6:$G$43,"<>Không áp dụng")),0) -> 0.68421053 | G4: CÓ MINH CHỨNG | H4: =IFERROR(COUNTIFS($I$6:$I$43,"<>",$G$6:$G$43,"<>Không áp dụng")/(COUNTIFS($A$6:$A$43,"<>",$G$6:$G$43,"<>Không áp dụng")),0) -> 1 | I4: HOÀN THÀNH ĐỦ MINH CHỨNG | J4: =IFERROR(COUNTIFS($G$6:$G$43,"Hoàn thành",$J$6:$J$43,"Đạt",$I$6:$I$43,"<>")/(COUNTIFS($A$6:$A$43,"<>",$G$6:$G$43,"<>Không áp dụng")),0) -> 0.68421053 | K4: Xem chi tiết tại 08_TongHopGV
A5: ID | B5: Nhóm | C5: Mức độ | D5: Yêu cầu cần chứng minh | E5: Minh chứng mong đợi | F5: Owner | G5: Trạng thái | H5: % HT | I5: Link/Path minh chứng | J5: Kết quả tự kiểm tra | K5: Ghi chú/lỗi còn lại
A6: BP01 | B6: Blueprint | C6: Bắt buộc | D6: Tài liệu mô tả kiến trúc tổng thể, thành phần, giao tiếp, ảnh hưởng khi một phần lỗi. | E6: design.md/blueprint.pdf; lập luận lựa chọn kiến trúc | F6: Huỳnh Thái Toàn | G6: Hoàn thành | H6: 100 | I6: blueprint/01-system-design.md blueprint/03-high-level-architecture.md | J6: Đạt | K6: Đã đối chiếu với code; còn xuất PDF và upload Drive ở SB02.
A7: BP02 | B7: Blueprint | C7: Bắt buộc | D7: C4 Level 1 – System Context: actors và hệ thống ngoài. | E7: Sơ đồ + mô tả Khán giả, Ban tổ chức, Soát vé, VNPAY/MoMo, AI, CSV | F7: Huỳnh Thái Toàn | G7: Hoàn thành | H7: 100 | I7: blueprint/02-c4-diagrams.md — System Context | J7: Đạt | K7: Cần kiểm tra Mermaid render rõ trong PDF cuối.
A8: BP03 | B8: Blueprint | C8: Bắt buộc | D8: C4 Level 2 – Container: web, mobile, backend, database, broker/cache... | E8: Sơ đồ có công nghệ và giao tiếp giữa container | F8: Huỳnh Thái Toàn | G8: Hoàn thành | H8: 100 | I8: blueprint/02-c4-diagrams.md — Container | J8: Đạt | K8: Demo không dùng broker ngoài; tài liệu đã ghi durable DB records/outbox thay thế.
A9: BP04 | B9: Blueprint | C9: Bắt buộc | D9: High-Level Architecture Diagram, nhấn mạnh payment, AI, CSV và offline check-in. | E9: Sơ đồ luồng dữ liệu/phụ thuộc và failure boundary | F9: Huỳnh Thái Toàn | G9: Hoàn thành | H9: 100 | I9: blueprint/03-high-level-architecture.md | J9: Đạt | K9: Nên xuất sơ đồ độ phân giải cao khi đóng gói bài nộp.
A10: BP05 | B10: Blueprint | C10: Bắt buộc | D10: Thiết kế dữ liệu: SQL/NoSQL/kết hợp và schema entity quan trọng. | E10: ERD/schema + giải thích lựa chọn và consistency | F10: Võ Hoàng Danh | G10: Hoàn thành | H10: 100 | I10: blueprint/04-database-design.md src/backend-api/prisma/schema.prisma | J10: Đạt | K10: Không còn lỗi bắt buộc; mở thêm migration/schema khi vấn đáp.
A11: BP06 | B11: Blueprint | C11: Chọn ít nhất 2 luồng | D11: Luồng mua vé từ bấm mua đến nhận e-ticket; có xử lý lỗi giữa chừng. | E11: Sequence/activity diagram hoặc mô tả bước + lỗi | F11: Võ Hoàng Danh | G11: Hoàn thành | H11: 100 | I11: blueprint/05-business-flows.md src/backend-api/test/checkout-flow.e2e-spec.ts | J11: Đạt | K11: Thiếu clip checkout tập trung; được theo dõi tại IM02.
A12: BP07 | B12: Blueprint | C12: Chọn ít nhất 2 luồng | D12: Luồng soát vé mất mạng và đồng bộ lại; tránh vé vào hai lần. | E12: Sequence/state diagram + conflict handling | F12: Nguyễn Minh Tú | G12: Hoàn thành | H12: 100 | I12: blueprint/core-design-decisions/offline-check-in.md src/backend-api/test/scanner-check-in-sync.e2e-spec.ts | J12: Đạt | K12: Conflict policy đã có; public-key manifest verification vẫn là hardening production.
A13: BP08 | B13: Blueprint | C13: Chọn ít nhất 2 luồng | D13: Luồng nhập Guest List CSV; xử lý file lỗi và dữ liệu trùng. | E13: Flow + validation + idempotent import | F13: Nguyễn Hữu Phúc | G13: Hoàn thành | H13: 100 | I13: blueprint/core-design-decisions/guest-list-csv-import.md src/backend-api/src/modules/guest-list/guest-list-import.service.ts | J13: Đạt | K13: Cần kèm bộ CSV valid/invalid trong gói minh chứng Drive.
A14: BP09 | B14: Blueprint | C14: Bắt buộc | D14: Thiết kế kiểm soát truy cập cho Khán giả, Ban tổ chức, Nhân sự soát vé. | E14: Role-permission matrix + enforcement tại endpoint/UI/app | F14: Nguyễn Minh Tú | G14: Hoàn thành | H14: 100 | I14: blueprint/06-access-control.md src/backend-api/src/modules/auth/roles.guard.ts | J14: Đạt | K14: Nên xuất một report test RBAC tổng hợp để giảng viên kiểm tra nhanh.
A15: BP10 | B15: Blueprint | C15: Bắt buộc | D15: Giải pháp tải đột biến/rate limiting cho 80.000 người trong 5 phút, 70% ở phút đầu. | E15: Thuật toán, ngưỡng, key giới hạn, hành vi khi vượt ngưỡng | F15: Nguyễn Hữu Phúc | G15: Hoàn thành | H15: 100 | I15: blueprint/core-design-decisions/sale-traffic-spike.md src/backend-api/src/common/cache/rate-limit.guard.ts | J15: Đạt | K15: Thiết kế đạt; báo cáo K6/load test còn thiếu được theo dõi tại IM12.
A16: BP11 | B16: Blueprint | C16: Bắt buộc | D16: Circuit Breaker + Graceful Degradation khi VNPAY/MoMo lỗi. | E16: Closed/Open/Half-Open, threshold, fallback | F16: Nguyễn Hữu Phúc | G16: Hoàn thành | H16: 100 | I16: blueprint/core-design-decisions/unstable-payment-gateway.md payment-circuit-breaker.service.ts | J16: Đạt | K16: MoMo chưa có adapter; provider port cùng mock/VNPAY chứng minh khả năng mở rộng.
A17: BP12 | B17: Blueprint | C17: Bắt buộc | D17: Idempotency Key chống trừ tiền hai lần. | E17: Cách sinh/lưu/check key, TTL, response khi lặp | F17: Võ Hoàng Danh | G17: Hoàn thành | H17: 100 | I17: blueprint/core-design-decisions/unstable-payment-gateway.md src/backend-api/src/common/idempotency/idempotency.service.ts | J17: Đạt | K17: Idempotency record giữ 90 ngày; cần nêu rõ thay vì nói TTL 24 giờ.
... A43: SB05 | B43: Nộp bài | C43: Bắt buộc | D43: File text tên mã-nhóm_mssv1_...txt; nội dung là link Drive public. | E43: Tên file và nội dung file text | F43: Võ Hoàng Danh | G43: Chưa làm | H43: 0 | I43: [BỔ SUNG] mã-nhóm_mssv1_mssv2_mssv3_mssv4.txt | J43: Chưa kiểm tra | K43: Tạo file text sau khi chốt link Drive public; nội dung chỉ chứa link Drive.

Sheet 03_PhanCongTask
A1: PHÂN CÔNG VÀ TỰ KHAI BÁO CÔNG VIỆC CÁ NHÂN
A3: Mỗi dòng là một task đủ cụ thể. Không ghi chung chung như “làm backend”. Ví dụ tốt: “Cài Idempotency-Key middleware, lưu key trong Redis TTL 24h và viết 5 test retry payment”.
A5: Task ID | B5: Requirement ID | C5: Nhóm nội dung | D5: Mô tả task cụ thể | E5: Sản phẩm/tiêu chí hoàn thành | F5: Người chính | G5: Người phối hợp | H5: Độ khó 1–5 | I5: Vai trò | J5: % HT | K5: Chất lượng 1–5 | L5: Link/ID minh chứng | M5: Giải thích đóng góp cá nhân | N5: Điểm công việc
A6: T01 | B6: BP15 | C6: Blueprint | D6: Rà soát yêu cầu và cấu trúc bộ Blueprint; bổ sung acceptance criteria, error scenario và liên kết giữa các tài liệu. | E6: Blueprint/specs có cấu trúc rõ, các yêu cầu bắt buộc được truy vết và review chéo. | F6: Nguyễn Minh Tú | G6: Huỳnh Thái Toàn | H6: 3 | I6: Chính | J6: 100 | K6: 4 | L6: Issue #1; PR #2/#3 | M6: Tú rà soát yêu cầu, chỉnh tài liệu reliability và chuẩn hóa phần đặc tả để nhóm bám theo khi cài đặt. | N6: 2.88
A7: T02 | B7: IM02 | C7: Cài đặt | D7: Xây luồng reservation → order → payment → ticket và phát hành e-ticket QR sau khi thanh toán thành công. | E7: Luồng end-to-end tạo đúng record, webhook idempotent và chỉ phát hành vé một lần. | F7: Nguyễn Minh Tú | G7: Võ Hoàng Danh | H7: 5 | I7: Chính | J7: 100 | K7: 5 | L7: Issue #6; PR #10 | M7: Tú triển khai nghiệp vụ lõi order/payment/ticket, trạng thái lỗi giữa chừng và QR ticket trong backend. | N7: 6
A8: T03 | B8: IM03 | C8: Cài đặt | D8: Cài quota ledger và khóa theo user/ticket type để giới hạn vé vẫn đúng khi nhiều request đồng thời. | E8: paidCount + reservedCount không vượt perUserLimit; request vượt hạn mức trả quota_exceeded. | F8: Nguyễn Minh Tú | G8: Võ Hoàng Danh | H8: 5 | I8: Chính | J8: 100 | K8: 5 | L8: PR #10; checkout-flow.e2e-spec.ts | M8: Tú cài transaction quota và các test concurrent để chứng minh cùng tài khoản không vượt giới hạn. | N8: 6
A9: T04 | B9: IM11 | C9: Kiểm thử | D9: Cài khóa inventory và viết test hai người đồng thời mua vé cuối cùng. | E9: Một request thành công, request còn lại nhận sold_out; reserved + sold không vượt capacity. | F9: Nguyễn Minh Tú | G9: Huỳnh Thái Toàn | H9: 5 | I9: Chính | J9: 100 | K9: 5 | L9: PR #10; test last-ticket contention | M9: Tú xây invariant chống oversell bằng FOR UPDATE và kiểm thử tranh chấp vé cuối cùng. | N9: 6
A10: T05 | B10: IM07 | C10: Cài đặt | D10: Xây check-in backend, manifest theo assignment/device và API đồng bộ kết quả quét QR. | E10: Scanner chỉ tải đúng manifest được cấp; backend trả accepted/conflict/rejected có log truy vết. | F10: Nguyễn Minh Tú | G10: Nguyễn Hữu Phúc | H10: 5 | I10: Chính | J10: 100 | K10: 5 | L10: Issue #20; PR #23/#31 | M10: Tú phụ trách Check-in Module, manifest, device binding và hợp đồng API phục vụ scanner. | N10: 6
A11: T06 | B11: IM08 | C11: Cài đặt | D11: Triển khai Scanner PWA offline queue, lưu bền vững và tự đồng bộ lại khi có mạng. | E11: Reload không mất queue; hai thiết bị quét cùng vé cho một accepted và một conflict khi sync. | F11: Nguyễn Minh Tú | G11: Nguyễn Hữu Phúc | H11: 5 | I11: Chính | J11: 100 | K11: 5 | L11: Issue #21; PR #23/#31 | M11: Tú xây PWA offline-first, clientEventId idempotent, xử lý ACK và hiển thị conflict cho nhân sự cổng. | N11: 6
A12: T07 | B12: IM06 | C12: Cài đặt | D12: Bổ sung giao diện quản lý scanner device/assignment và seed dữ liệu phục vụ phân quyền tại cổng. | E12: Admin tạo/gán thiết bị được; scanner chỉ truy cập assignment hợp lệ và có dữ liệu demo. | F12: Nguyễn Minh Tú | G12: Nguyễn Hữu Phúc | H12: 4 | I12: Chính | J12: 100 | K12: 4 | L12: Commit e5706b5/2506845 | M12: Tú hoàn thiện device management, scanner seed và sửa UI để luồng phân quyền có thể demo. | N12: 3.84
A13: T08 | B13: IM08 | C13: Kiểm thử | D13: Viết và chạy các kịch bản verify reload, scan workflow, sync recovery và retry cho Scanner PWA. | E13: Các script verify:* chạy được, queue không mất và retry không tạo check-in trùng. | F13: Nguyễn Minh Tú | G13: Huỳnh Thái Toàn | H13: 4 | I13: Chính | J13: 100 | K13: 5 | L13: PR #31; scanner-pwa/scripts/verify-* | M13: Tú bổ sung kiểm chứng tự động cho các failure path quan trọng của scanner offline. | N13: 4.8
A14: T09 | B14: BP05 | C14: Blueprint | D14: Thiết kế ERD, transaction boundary và quyết định dùng PostgreSQL cho inventory/order/payment/ticket. | E14: Có ERD, khóa/constraint chính và giải thích consistency chống oversell, quota sai. | F14: Võ Hoàng Danh | G14: Nguyễn Minh Tú | H14: 4 | I14: Chính | J14: 100 | K14: 5 | L14: Issue #1; PR #4 | M14: Danh chịu trách nhiệm phần Database & Transaction, rà soát entity và các invariant dữ liệu cốt lõi. | N14: 4.8
A15: T10 | B15: IM17 | C15: Cài đặt | D15: Xây backend core, Prisma schema/migration, Docker PostgreSQL/Redis và seed dữ liệu nền. | E15: Backend migrate/seed thành công; schema hỗ trợ concert, inventory, order, payment, ticket và user. | F15: Võ Hoàng Danh | G15: Nguyễn Minh Tú | H15: 5 | I15: Chính | J15: 100 | K15: 5 | L15: Issue #5; commit 3f2cf1f/635e290 | M15: Danh tạo nền tảng backend/database Phase 1, migration lịch sử và môi trường Docker để các module khác tích hợp. | N15: 6
A16: T11 | B16: IM12 | C16: Cài đặt | D16: Hoàn thiện structured logs, correlation ID, hardening verification và risk checks cho đường reservation/payment. | E16: Log có ngữ cảnh nhưng không lộ secret; request rủi ro bị chặn và có test/kiểm chứng tương ứng. | F16: Võ Hoàng Danh | G16: Huỳnh Thái Toàn | H16: 5 | I16: Chính | J16: 100 | K16: 5 | L16: Issue #16; PR #25 | M16: Danh cài lớp hardening, log vận hành và risk checks, đồng thời kiểm tra failure path trước khi merge. | N16: 6
A17: T12 | B17: IM06 | C17: Cài đặt | D17: Cài AuthGuard/RolesGuard và giới hạn quyền organizer, audience, scanner tại endpoint. | E17: Role sai nhận 403; tài nguyên admin còn được kiểm tra theo organization ownership. | F17: Võ Hoàng Danh | G17: Nguyễn Hữu Phúc | H17: 4 | I17: Chính | J17: 100 | K17: 4 | L17: Issue #5; commit 3f2cf1f | M17: Danh xây phần backend core/auth làm nền cho RBAC; phối hợp Phúc nối vào Admin API. | N17: 3.84
... A38: T33 | B38: IM04 | C38: Cài đặt | D38: Cài reminder trước 24 giờ, scheduled worker và adapter email/in-app có idempotency. | E38: Mỗi concert/user/channel chỉ tạo một reminder; worker retry được và lỗi gửi không ảnh hưởng nghiệp vụ mua vé. | F38: Huỳnh Thái Toàn | G38: Nguyễn Hữu Phúc | H38: 4 | I38: Chính | J38: 100 | K38: 5 | L38: Commit 67439cb | M38: Toàn hoàn thiện reminder scheduler/worker và phối hợp Phúc để giữ notification abstraction dễ mở rộng. | N38: 4.8

Sheet 05_DanhGiaCheo
A1: ĐÁNH GIÁ CHÉO GIỮA CÁC THÀNH VIÊN
A3: Mỗi thành viên đánh giá các thành viên còn lại, không tự đánh giá chính mình. Nhóm 1 thành viên để trống. Nhận xét phải có ví dụ cụ thể, tránh tất cả đều 5 điểm.
A5: STT | B5: Người đánh giá | C5: Người được đánh giá | D5: Mức đóng góp | E5: Đúng tiến độ | F5: Chất lượng đầu ra | G5: Chủ động xử lý vấn đề | H5: Hỗ trợ nhóm | I5: Khả năng giải thích phần việc | J5: Điểm TB | K5: Nhận xét cụ thể | L5: Ví dụ/minh chứng | M5: Xác nhận
A6: 1 | B6: Nguyễn Minh Tú | C6: Võ Hoàng Danh | D6: 5 | E6: 5 | F6: 5 | G6: 5 | H6: 4 | I6: 5 | J6: 4.83 | K6: Danh xây nền database/backend core chắc, đồng thời xử lý tốt hardening và AI pipeline. Nên gom các thay đổi backend lớn thành PR dễ review hơn và bổ sung thêm test tự động cho nhánh lỗi AI/hardening. | L6: PR #4 https://github.com/Toanapr/ticket-box/pull/4 PR #25 https://github.com/Toanapr/ticket-box/pull/25 AI commit https://github.com/Toanapr/ticket-box/commit/f274454 | M6: Có
A7: 2 | B7: Nguyễn Minh Tú | C7: Nguyễn Hữu Phúc | D7: 5 | E7: 5 | F7: 5 | G7: 5 | H7: 5 | I7: 4 | J7: 4.83 | K7: Phúc đóng góp rộng ở admin, cache/rate limit, guest list, AI và dashboard; phối hợp tích hợp nhanh. Một số PR có phạm vi rất lớn, nên tách theo feature và bổ sung regression test để việc review ổn định hơn. | L7: PR #18 https://github.com/Toanapr/ticket-box/pull/18 PR #28 https://github.com/Toanapr/ticket-box/pull/28 PR #32/#33 https://github.com/Toanapr/ticket-box/pull/32 | M7: Có
A8: 3 | B8: Nguyễn Minh Tú | C8: Huỳnh Thái Toàn | D8: 5 | E8: 5 | F8: 5 | G8: 5 | H8: 4 | I8: 5 | J8: 4.83 | K8: Toàn triển khai audience web và payment resilience tốt, nắm rõ contract giữa frontend và backend. Nên chuẩn hóa Git author và tăng test end-to-end cho checkout/notification để minh chứng nhất quán hơn. | L8: PR #19 https://github.com/Toanapr/ticket-box/pull/19 PR #22 https://github.com/Toanapr/ticket-box/pull/22 Notification commit https://github.com/Toanapr/ticket-box/commit/67439cb | M8: Có
A9: 4 | B9: Võ Hoàng Danh | C9: Nguyễn Minh Tú | D9: 5 | E9: 5 | F9: 5 | G9: 5 | H9: 4 | I9: 5 | J9: 4.83 | K9: Tú xử lý tốt các luồng khó về transaction payment, check-in manifest và scanner offline; chủ động hoàn thiện tích hợp. Cần bổ sung thêm test tự động cho offline conflict/sync retry và chia PR lớn thành các phần dễ kiểm tra. | L9: PR #10 https://github.com/Toanapr/ticket-box/pull/10 PR #23 https://github.com/Toanapr/ticket-box/pull/23 PR #31 https://github.com/Toanapr/ticket-box/pull/31 | M9: Có
A10: 5 | B10: Võ Hoàng Danh | C10: Nguyễn Hữu Phúc | D10: 5 | E10: 5 | F10: 5 | G10: 5 | H10: 5 | I10: 4 | J10: 4.83 | K10: Phúc hoàn thành nhiều module quan trọng và hỗ trợ nối admin với backend hiệu quả. Nên giới hạn phạm vi từng PR, ghi rõ checklist test và tăng coverage cho guest list, AI và refund workflow. | L10: PR #18 https://github.com/Toanapr/ticket-box/pull/18 PR #28 https://github.com/Toanapr/ticket-box/pull/28 PR #32/#33 https://github.com/Toanapr/ticket-box/pull/32 | M10: Có
A11: 6 | B11: Võ Hoàng Danh | C11: Huỳnh Thái Toàn | D11: 5 | E11: 5 | F11: 5 | G11: 5 | H11: 4 | I11: 5 | J11: 4.83 | K11: Toàn làm tốt audience UX, payment resilience và các quyết định tích hợp quan trọng; phản hồi vấn đề contract nhanh. Phần notification/payment nên có thêm kịch bản lỗi end-to-end và tài liệu demo tập trung. | L11: PR #19 https://github.com/Toanapr/ticket-box/pull/19 PR #22 https://github.com/Toanapr/ticket-box/pull/22 Notification commit https://github.com/Toanapr/ticket-box/commit/67439cb | M11: Có
A12: 7 | B12: Nguyễn Hữu Phúc | C12: Nguyễn Minh Tú | D12: 5 | E12: 4 | F12: 5 | G12: 5 | H12: 5 | I12: 5 | J12: 4.83 | K12: Tú đảm nhiệm tốt backend payment và scanner/check-in offline, giải thích được các invariant quan trọng. Nên cập nhật tiến độ và mô tả PR đều hơn, đồng thời bổ sung test cho conflict nhiều thiết bị và manifest hết hạn. | L12: PR #10 https://github.com/Toanapr/ticket-box/pull/10 PR #23 https://github.com/Toanapr/ticket-box/pull/23 PR #31 https://github.com/Toanapr/ticket-box/pull/31 | M12: Có
A13: 8 | B13: Nguyễn Hữu Phúc | C13: Võ Hoàng Danh | D13: 5 | E13: 5 | F13: 5 | G13: 5 | H13: 4 | I13: 5 | J13: 4.67 | K13: Danh xử lý vững phần database, backend core, log hardening và AI worker; sẵn sàng hỗ trợ khi có lỗi nền tảng. Cần làm lịch sử PR rõ hơn cho backend core/AI và bổ sung test tích hợp để nhóm dễ truy vết chất lượng. | L13: PR #4 https://github.com/Toanapr/ticket-box/pull/4 PR #25 https://github.com/Toanapr/ticket-box/pull/25 AI commit https://github.com/Toanapr/ticket-box/commit/f274454 | M13: Có
A14: 9 | B14: Nguyễn Hữu Phúc | C14: Huỳnh Thái Toàn | D14: 5 | E14: 5 | F14: 5 | G14: 5 | H14: 5 | I14: 4 | J14: 4.83 | K14: Toàn giữ tốt luồng audience, payment và tài liệu kiến trúc; hỗ trợ nhóm chốt contract và UX. Nên chuẩn hóa tên tác giả commit, gom minh chứng demo và bổ sung regression test cho các thay đổi xuyên module. | L14: PR #19 https://github.com/Toanapr/ticket-box/pull/19 PR #22 https://github.com/Toanapr/ticket-box/pull/22 Notification commit https://github.com/Toanapr/ticket-box/commit/67439cb | M14: Có
A15: 10 | B15: Huỳnh Thái Toàn | C15: Nguyễn Minh Tú | D15: 5 | E15: 5 | F15: 5 | G15: 5 | H15: 4 | I15: 5 | J15: 4.83 | K15: Tú hoàn thành các luồng có độ khó cao về reservation/payment và offline check-in; phối hợp tích hợp scanner tốt. Cần tăng test tự động cho retry/conflict và ghi rõ phạm vi thay đổi khi PR chạm nhiều file. | L15: PR #10 https://github.com/Toanapr/ticket-box/pull/10 PR #23 https://github.com/Toanapr/ticket-box/pull/23 PR #31 https://github.com/Toanapr/ticket-box/pull/31 | M15: Có
A16: 11 | B16: Huỳnh Thái Toàn | C16: Võ Hoàng Danh | D16: 5 | E16: 5 | F16: 5 | G16: 5 | H16: 4 | I16: 5 | J16: 4.83 | K16: Danh xây nền backend/database tốt, xử lý hardening và AI pipeline có chiều sâu; hỗ trợ sửa lỗi tích hợp nhanh. Nên tăng test cho failure path, chuẩn hóa quy trình PR và ghi hướng dẫn demo ngắn cho các module backend khó. | L16: PR #4 https://github.com/Toanapr/ticket-box/pull/4 PR #25 https://github.com/Toanapr/ticket-box/pull/25 AI commit https://github.com/Toanapr/ticket-box/commit/f274454 | M16: Có
A17: 12 | B17: Huỳnh Thái Toàn | C17: Nguyễn Hữu Phúc | D17: 5 | E17: 5 | F17: 5 | G17: 5 | H17: 5 | I17: 4 | J17: 4.83 | K17: Phúc có khối lượng đóng góp lớn ở admin, cache, guest list, AI và dashboard; chủ động xử lý nhiều lỗi tích hợp. Nên tách PR theo chức năng và bổ sung checklist regression để hạn chế rủi ro khi thay đổi nhiều module cùng lúc. | L17: PR #18 https://github.com/Toanapr/ticket-box/pull/18 PR #28 https://github.com/Toanapr/ticket-box/pull/28 PR #32/#33 https://github.com/Toanapr/ticket-box/pull/32 | M17: Có

Sheet 04_TuDanhGia
A1: TỰ ĐÁNH GIÁ CÁ NHÂN — MỖI THÀNH VIÊN MỘT DÒNG
A3: Thang 1–5: 1 = gần như chưa tham gia/không giải thích được; 3 = hoàn thành phần được giao; 5 = chủ động, có minh chứng rõ và giải thích được quyết định kỹ thuật khi vấn đáp.
A5: STT | B5: Thành viên | C5: Hiểu bài toán | D5: Blueprint/kiến trúc | E5: Cài đặt nghiệp vụ | F5: Cơ chế kỹ thuật | G5: Kiểm thử/chất lượng | H5: Tài liệu/README | I5: Demo/video | J5: Hợp tác nhóm | K5: Khả năng vấn đáp | L5: Điểm TB | M5: 3 đóng góp quan trọng nhất | N5: Phần chưa hoàn thành/hạn chế | O5: Minh chứng tiêu biểu | P5: Tỷ lệ đóng góp tự khai (%) | Q5: Cam kết trung thực
A6: 1 | B6: Nguyễn Minh Tú | C6: 5 | D6: 4 | E6: 5 | F6: 5 | G6: 4 | H6: 4 | I6: 4 | J6: 5 | K6: 5 | L6: 4.56 | M6: 1) Hoàn thiện backend reservation/order/payment/ticket với transaction, quota và idempotency; 2) Xây check-in backend và manifest; 3) Triển khai scanner PWA offline queue, sync và device management. | N6: Một số PR có phạm vi lớn và lịch sử PR trùng/đóng; cần tách thay đổi nhỏ hơn, cập nhật mô tả tiến độ đều hơn và bổ sung test tự động cho conflict nhiều thiết bị, manifest hết hạn và sync retry. | O6: PR #10 https://github.com/Toanapr/ticket-box/pull/10 PR #23 https://github.com/Toanapr/ticket-box/pull/23 PR #31 https://github.com/Toanapr/ticket-box/pull/31 | P6: 0.24 | Q6: Có
A7: 2 | B7: Võ Hoàng Danh | C7: 5 | D7: 5 | E7: 5 | F7: 5 | G7: 4 | H7: 4 | I7: 4 | J7: 5 | K7: 5 | L7: 4.67 | M7: 1) Thiết kế database, migration và backend core; 2) Hoàn thiện structured logs, hardening verification và risk checks; 3) Xây AI Artist Bio backend pipeline và hỗ trợ sửa lỗi UI admin. | N7: Backend core và AI còn thiếu lịch sử PR tập trung, một phần được đưa vào qua commit trực tiếp; cần bổ sung integration test cho failure path, chuẩn hóa quy trình PR và viết hướng dẫn demo ngắn cho các module backend khó. | O7: PR #4 https://github.com/Toanapr/ticket-box/pull/4 PR #25 https://github.com/Toanapr/ticket-box/pull/25 Core/AI https://github.com/Toanapr/ticket-box/commit/3f2cf1f | https://github.com/Toanapr/ticket-box/commit/f274454 | P7: 0.2 | Q7: Có
A8: 3 | B8: Nguyễn Hữu Phúc | C8: 5 | D8: 5 | E8: 5 | F8: 5 | G8: 4 | H8: 5 | I8: 4 | J8: 5 | K8: 5 | L8: 4.78 | M8: 1) Xây admin, notification, revenue dashboard và refund workflow; 2) Triển khai Redis cache-aside và rate limiting; 3) Hoàn thiện guest list CSV, AI Artist Bio và nhiều lượt sửa lỗi tích hợp. | N8: Một số PR như phần admin tổng hợp có phạm vi rất lớn; cần tách theo feature, ghi checklist test rõ hơn và tăng regression test cho guest list failure, AI review/publish và refund workflow. | O8: PR #18 https://github.com/Toanapr/ticket-box/pull/18 PR #28 https://github.com/Toanapr/ticket-box/pull/28 PR #30/#32/#33 https://github.com/Toanapr/ticket-box/pull/30 | P8: 0.28 | Q8: Có
A9: 4 | B9: Huỳnh Thái Toàn | C9: 5 | D9: 5 | E9: 5 | F9: 5 | G9: 5 | H9: 5 | I9: 4 | J9: 5 | K9: 5 | L9: 4.89 | M9: 1) Dẫn dắt kiến trúc/blueprint và triển khai audience web; 2) Hoàn thiện payment resilience, durable idempotency, reconciliation và VNPAY; 3) Tích hợp notification reminder, API contract và cải thiện checkout UX. | N9: Tên Git author còn chưa thống nhất giữa Toan Huynh/Toàn Huỳnh/Lab User; cần chuẩn hóa để truy vết minh chứng, đồng thời bổ sung thêm test end-to-end checkout/notification và gom tài liệu demo tập trung. | O9: PR #19 https://github.com/Toanapr/ticket-box/pull/19 PR #22 https://github.com/Toanapr/ticket-box/pull/22 Notification https://github.com/Toanapr/ticket-box/commit/67439cb | P9: 0.28 | Q9: Có

Sheet 06_MinhChung_NopBai
A1: DANH MỤC MINH CHỨNG VÀ KIỂM TRA GOOGLE DRIVE
A3: A. DANH MỤC MINH CHỨNG
A5: ID | B5: Loại | C5: Requirement ID | D5: Thành viên | E5: Mô tả minh chứng | F5: URL/Path | G5: Ngày | H5: Cách kiểm tra | I5: Kết quả | J5: Ghi chú
A6: MC01 | B6: Tài liệu | C6: BP01 | D6: Huỳnh Thái Toàn | E6: Tài liệu kiến trúc tổng thể, thành phần, giao tiếp và failure isolation. | F6: https://github.com/Toanapr/ticket-box/blob/dev/blueprint/01-system-design.md | G6: 46216 | H6: Mở tài liệu; đối chiếu kiến trúc modular monolith, async path và ảnh hưởng khi dependency lỗi. | I6: Đạt
A7: MC02 | B7: Sơ đồ | C7: BP02 | D7: Huỳnh Thái Toàn | E7: C4 Level 1 — System Context và các actor/hệ thống ngoài. | F7: https://github.com/Toanapr/ticket-box/blob/dev/blueprint/02-c4-diagrams.md | G7: 46216 | H7: Mở phần System Context; kiểm tra audience, organizer, scanner, payment, AI và CSV. | I7: Đạt
A8: MC03 | B8: Sơ đồ | C8: BP03 | D8: Huỳnh Thái Toàn | E8: C4 Level 2 — Container cho web, scanner, backend, database, Redis và broker/storage. | F8: https://github.com/Toanapr/ticket-box/blob/dev/blueprint/02-c4-diagrams.md | G8: 46216 | H8: Mở phần Container; kiểm tra công nghệ và hướng giao tiếp giữa container. | I8: Đạt
A9: MC04 | B9: Sơ đồ | C9: BP04 | D9: Huỳnh Thái Toàn | E9: High-level architecture thể hiện payment, AI, CSV, offline check-in và failure boundary. | F9: https://github.com/Toanapr/ticket-box/blob/dev/blueprint/03-high-level-architecture.md | G9: 46216 | H9: Đối chiếu critical path, async path và graceful degradation. | I9: Đạt
A10: MC05 | B10: Tài liệu | C10: BP05 | D10: Võ Hoàng Danh | E10: Thiết kế dữ liệu và invariant cho reservation, order, payment, ticket, inventory và quota. | F10: https://github.com/Toanapr/ticket-box/blob/dev/blueprint/04-database-design.md | G10: 46216 | H10: Kiểm tra entity, unique constraint, status và transaction boundary. | I10: Đạt
A11: MC06 | B11: Sơ đồ | C11: BP06 | D11: Võ Hoàng Danh | E11: Luồng mua vé từ reserve đến payment và phát hành e-ticket, gồm failure path. | F11: https://github.com/Toanapr/ticket-box/blob/dev/blueprint/05-business-flows.md | G11: 46216 | H11: Theo dõi reserve → order → payment → ticket và các nhánh timeout/retry. | I11: Đạt
A12: MC07 | B12: Tài liệu | C12: BP07 | D12: Nguyễn Hữu Phúc | E12: Thiết kế offline check-in, durable queue, manifest và conflict policy. | F12: https://github.com/Toanapr/ticket-box/blob/dev/blueprint/core-design-decisions/offline-check-in.md | G12: 46216 | H12: Kiểm tra manifest TTL, local queue, ACK và duplicate/conflict handling. | I12: Đạt
A13: MC08 | B13: Tài liệu | C13: BP08 | D13: Nguyễn Hữu Phúc | E13: Thiết kế Guest List CSV với staging, validation, dedupe và publish all-or-nothing. | F13: https://github.com/Toanapr/ticket-box/blob/dev/blueprint/core-design-decisions/guest-list-csv-import.md | G13: 46216 | H13: Đối chiếu validation, duplicate, idempotency và failure isolation. | I13: Đạt
A14: MC09 | B14: Tài liệu | C14: BP09 | D14: Nguyễn Minh Tú | E14: RBAC, ownership và scanner access control matrix. | F14: https://github.com/Toanapr/ticket-box/blob/dev/blueprint/06-access-control.md | G14: 46216 | H14: Kiểm tra quyền audience/organizer/scanner và ownership tại API. | I14: Đạt
A15: MC10 | B15: Tài liệu | C15: BP10 | D15: Nguyễn Hữu Phúc | E15: Thiết kế bảo vệ traffic spike, rate limit, fairness và backpressure. | F15: https://github.com/Toanapr/ticket-box/blob/dev/blueprint/core-design-decisions/sale-traffic-spike.md | G15: 46216 | H15: Kiểm tra key giới hạn, ngưỡng, 429/Retry-After và hành vi quá tải. | I15: Đạt
A16: MC11 | B16: Tài liệu | C16: BP11 | D16: Nguyễn Hữu Phúc | E16: Circuit breaker và graceful degradation khi payment provider lỗi. | F16: https://github.com/Toanapr/ticket-box/blob/dev/blueprint/core-design-decisions/unstable-payment-gateway.md | G16: 46216 | H16: Kiểm tra Closed/Open/Half-Open, timeout, fallback và reconciliation. | I16: Đạt
A17: MC12 | B17: Tài liệu | C17: BP12 | D17: Võ Hoàng Danh | E17: Thiết kế durable idempotency cho reservation/payment/webhook. | F17: https://github.com/Toanapr/ticket-box/blob/dev/blueprint/core-design-decisions/unstable-payment-gateway.md | G17: 46216 | H17: Kiểm tra cách sinh/lưu key, replay response và xử lý request trùng. | I17: Đạt
... A21: MC16 | B21: Pull request | C21: IM01 | D21: Huỳnh Thái Toàn | E21: Audience web: concert list/detail, checkout UI, ticket QR, poster và seating map. | F21: https://github.com/Toanapr/ticket-box/pull/22 | G21: 46216 | H21: Mở Files changed; đối chiếu các route concert, checkout, order và ticket. | I21: Đạt
A22: MC17 | B22: Test report | C22: IM02 | D22: Nguyễn Minh Tú | E22: Checkout end-to-end từ reservation đến payment success và issued ticket QR. | F22: https://github.com/Toanapr/ticket-box/blob/dev/src/backend-api/test/checkout-flow.e2e-spec.ts TODO_EVIDENCE_IM02_CHECKOUT_VIDEO_OR_TEST_RUN_URL | G22: 46216 | H22: Chạy checkout-flow e2e; kiểm tra DB records và quay clip luồng UI đến QR. | I22: Chưa kiểm tra | J22: Thiếu video hoặc log test đã chạy. Bổ sung URL Drive/GitHub Actions vào placeholder IM02.
A23: MC18 | B23: Test report | C23: IM03 | D23: Nguyễn Minh Tú | E23: Test quota tài khoản dưới parallel requests. | F23: https://github.com/Toanapr/ticket-box/blob/dev/src/backend-api/test/checkout-flow.e2e-spec.ts TODO_EVIDENCE_IM03_QUOTA_TEST_RUN_URL | G23: 46216 | H23: Chạy test 'does not let one user exceed quota with parallel requests'; lưu output. | I23: Chưa kiểm tra | J23: Đã có test code nhưng chưa có report/log chạy đính kèm.
A24: MC19 | B24: Source code | C24: IM04 | D24: Nguyễn Hữu Phúc | E24: Notification adapters, worker, email/in-app và reminder scheduler 24 giờ. | F24: https://github.com/Toanapr/ticket-box/tree/dev/src/backend-api/src/modules/notification https://github.com/Toanapr/ticket-box/blob/dev/src/backend-api/src/modules/notification/notification-reminder.scheduler.spec.ts | G24: 46216 | H24: Mở adapter/worker/scheduler; chạy unit test và kiểm tra lỗi notification không rollback ticket. | I24: Đạt | J24: Nên bổ sung ảnh email/in-app hoặc video accelerated-clock trước khi nộp.
A25: MC20 | B25: Pull request | C25: IM05 | D25: Nguyễn Hữu Phúc | E25: Admin CRUD concert/ticket type, dashboard doanh thu và refund workflow. | F25: https://github.com/Toanapr/ticket-box/pull/33 | G25: 46216 | H25: Mở Files changed và trang admin dashboard/concert operations; kiểm tra API ownership. | I25: Đạt
A26: MC21 | B26: Source code | C26: IM06 | D26: Võ Hoàng Danh | E26: RBAC/ownership được cài ở auth guard, roles guard, admin và scanner APIs. | F26: https://github.com/Toanapr/ticket-box/tree/dev/src/backend-api/src/modules/auth https://github.com/Toanapr/ticket-box/blob/dev/src/backend-api/test/scanner-assignment.e2e-spec.ts | G26: 46216 | H26: Chạy auth/admin/scanner tests với role đúng và sai; kiểm tra 401/403/ownership. | I26: Đạt | J26: Nên xuất một test report RBAC tổng hợp để minh chứng dễ chấm.
A27: MC22 | B27: Source code | C27: IM07 | D27: Nguyễn Minh Tú | E27: Scanner mobile/PWA quét QR, validate và tạo check-in record. | F27: https://github.com/Toanapr/ticket-box/tree/dev/src/scanner-mobile https://github.com/Toanapr/ticket-box/tree/dev/src/scanner-pwa/src/app/scanner | G27: 46216 | H27: Mở ScanScreen/scan.ts và scanner page; demo camera hoặc nhập QR thủ công. | I27: Đạt | J27: Thiếu video quay trên thiết bị thật; có thể bổ sung vào Drive.
A28: MC23 | B28: Test report | C28: IM08 | D28: Nguyễn Minh Tú | E28: Offline queue, reload persistence, sync retry và conflict hai thiết bị. | F28: https://github.com/Toanapr/ticket-box/blob/dev/src/backend-api/test/scanner-check-in-sync.e2e-spec.ts https://github.com/Toanapr/ticket-box/tree/dev/src/scanner-pwa/scripts TODO_EVIDENCE_IM08_OFFLINE_DEMO_VIDEO_URL | G28: 46216 | H28: Chạy scanner e2e và verify-* scripts; quay video tắt/bật mạng và conflict. | I28: Chưa kiểm tra | J28: Đã có test/script nhưng thiếu log chạy và video offline demo đính kèm.
A29: MC24 | B29: Test report | C29: IM09 | D29: Võ Hoàng Danh | E29: AI Artist Bio: upload PDF, extract/sanitize, provider, draft review/publish và retry. | F29: https://github.com/Toanapr/ticket-box/blob/dev/src/backend-api/src/modules/artist-bio/artist-bio.service.spec.ts https://github.com/Toanapr/ticket-box/blob/dev/docs/test-data/artist-press-kit-multi-artist-test.pdf | G29: 46216 | H29: Chạy artist-bio specs với PDF mẫu; kiểm tra READY/FAILED, edit và publish. | I29: Đạt | J29: Nên bổ sung ảnh trang review/publish hoặc video demo AI job.
A30: MC25 | B30: Test report | C30: IM10 | D30: Nguyễn Hữu Phúc | E30: Guest List CSV import với 18 scenario validation, duplicate và failure isolation. | F30: https://github.com/Toanapr/ticket-box/blob/dev/src/backend-api/src/modules/guest-list/guest-list-import.service.spec.ts https://github.com/Toanapr/ticket-box/tree/dev/docs/test-data/guest-list-scenarios | G30: 46216 | H30: Chạy guest-list specs với scenario valid/invalid; kiểm tra version active không bị ghi đè khi lỗi. | I30: Đạt
A31: MC26 | B31: Test report | C31: IM11 | D31: Nguyễn Minh Tú | E31: Concurrency test không oversell vé cuối cùng. | F31: https://github.com/Toanapr/ticket-box/blob/dev/src/backend-api/test/checkout-flow.e2e-spec.ts TODO_EVIDENCE_IM11_OVERSELL_TEST_RUN_URL | G31: 46216 | H31: Chạy test 'does not oversell the last available ticket under concurrent requests'; lưu log. | I31: Chưa kiểm tra | J31: Đã có test code nhưng chưa có report/log chạy đính kèm.
A32: MC27 | B32: Test report | C32: IM12 | D32: Nguyễn Hữu Phúc | E32: Rate-limit guard và test trả 429/Retry-After cho reservation spam. | F32: https://github.com/Toanapr/ticket-box/blob/dev/src/backend-api/src/common/cache/rate-limit.guard.spec.ts https://github.com/Toanapr/ticket-box/blob/dev/src/backend-api/test/checkout-flow.e2e-spec.ts TODO_EVIDENCE_IM12_K6_REPORT_URL | G32: 46216 | H32: Chạy unit/e2e và load test; kiểm tra RPS, 429 và database không quá tải. | I32: Chưa kiểm tra | J32: Thiếu K6/load-test report hoặc GitHub Actions artifact. Bổ sung vào placeholder IM12.
A33: MC28 | B33: Test report | C33: IM13 | D33: Huỳnh Thái Toàn | E33: Circuit breaker implementation và state-transition unit tests. | F33: https://github.com/Toanapr/ticket-box/blob/dev/src/backend-api/src/modules/payment/resilience/payment-circuit-breaker.service.spec.ts TODO_EVIDENCE_IM13_CIRCUIT_TEST_RUN_URL | G33: 46216 | H33: Chạy spec; kiểm tra Closed → Open → Half-Open → Closed và public reads vẫn hoạt động. | I33: Chưa kiểm tra | J33: Thiếu log/report chạy test circuit breaker.
A34: MC29 | B34: Test report | C34: IM14 | D34: Huỳnh Thái Toàn | E34: Durable idempotency, webhook replay và reconciliation tests. | F34: https://github.com/Toanapr/ticket-box/blob/dev/src/backend-api/test/checkout-flow.e2e-spec.ts TODO_EVIDENCE_IM14_IDEMPOTENCY_TEST_RUN_URL | G34: 46216 | H34: Chạy các case duplicate reservation, webhook replay, lost webhook reconciliation; kiểm tra chỉ một ticket/payment. | I34: Chưa kiểm tra | J34: Thiếu report chạy test hoặc ảnh DB trước/sau retry.
A35: MC30 | B35: Test report | C35: IM15 | D35: Nguyễn Hữu Phúc | E35: Redis cache-aside, hit/miss budget và invalidation tests. | F35: https://github.com/Toanapr/ticket-box/blob/dev/src/backend-api/src/common/cache/cache.service.spec.ts https://github.com/Toanapr/ticket-box/blob/dev/src/backend-api/src/common/cache/cache-invalidation.service.ts TODO_EVIDENCE_IM15_CACHE_TEST_RUN_URL | G35: 46216 | H35: Chạy cache specs; kiểm tra hit/miss log, TTL và invalidation khi admin/payment cập nhật. | I35: Chưa kiểm tra | J35: Thiếu log/report chạy Redis cache và invalidation end-to-end.
A36: MC31 | B36: Tài liệu | C36: IM16 | D36: Huỳnh Thái Toàn | E36: README cấp repository để clone và chạy toàn bộ hệ thống. | F36: TODO_EVIDENCE_IM16_ROOT_README_URL | G36: 46216 | H36: Từ máy sạch, làm theo README để khởi động backend, audience, admin và scanner. | I36: Chưa đạt | J36: Repository chưa có README.md ở thư mục gốc. Cần tạo prerequisites, env, ports, commands, accounts và troubleshooting.
A37: MC32 | B37: Source code | C37: IM17 | D37: Võ Hoàng Danh | E37: Seed script có ít nhất 4 concert, ticket types SVIP/VIP/CAT1/CAT2/GA và seating-map keys. | F37: https://github.com/Toanapr/ticket-box/blob/dev/src/backend-api/prisma/seed.js | G37: 46216 | H37: Chạy seed; kiểm tra 4+ concert, ticket types, inventory counters và assets hiển thị. | I37: Đạt | J37: Nên lưu ảnh/log seed thành công làm minh chứng bổ sung.
A38: MC33 | B38: Test report | C38: IM18 | D38: Huỳnh Thái Toàn | E38: Khởi chạy và smoke test toàn bộ hệ thống theo Blueprint. | F38: TODO_EVIDENCE_IM18_ROOT_COMPOSE_OR_START_SCRIPT_URL TODO_EVIDENCE_IM18_FULL_SYSTEM_SMOKE_REPORT_URL | G38: 46216 | H38: Dùng một lệnh/script khởi động; smoke test audience → checkout → admin → scanner. | I38: Chưa kiểm tra | J38: Chưa có root compose/start script và report smoke end-to-end tập trung. Cần bổ sung trước khi nộp.
A39: MC34 | B39: Google Drive | C39: SB01 | D39: Võ Hoàng Danh | E39: Google Drive gốc public và mở được ở chế độ ẩn danh. | F39: TODO_DRIVE_ROOT_PUBLIC_URL | G39: 46216 | H39: Mở link bằng cửa sổ ẩn danh/tài khoản khác; kiểm tra quyền Viewer. | I39: Chưa kiểm tra | J39: Bổ sung link Drive public và ảnh kiểm tra quyền.
A40: MC35 | B40: Google Drive | C40: SB02 | D40: Võ Hoàng Danh | E40: Drive có blueprint.pdf hoặc thư mục blueprint đầy đủ. | F40: TODO_DRIVE_BLUEPRINT_URL | G40: 46216 | H40: Mở link trực tiếp; kiểm tra toàn bộ tài liệu blueprint và core decisions. | I40: Chưa kiểm tra | J40: Upload blueprint.pdf hoặc blueprint/ rồi thay placeholder.
A41: MC36 | B41: Google Drive | C41: SB03 | D41: Võ Hoàng Danh | E41: Drive có src/, data/ và README.md. | F41: TODO_DRIVE_SOURCE_DATA_README_URL | G41: 46216 | H41: Mở link; kiểm tra cấu trúc src/, data/ và README ở cấp gốc. | I41: Chưa đạt | J41: Hiện repository chưa có data/ và README.md cấp gốc; cần tạo và upload trước khi thay placeholder.
A42: MC37 | B42: Video demo | C42: SB04 | D42: Võ Hoàng Danh | E42: Video MP4 1080p khoảng 720 kbps, có camera thành viên và demo code/app. | F42: TODO_DRIVE_FINAL_DEMO_VIDEO_URL | G42: 46216 | H42: Mở video; kiểm tra phát được, có camera, kiến trúc và demo các luồng chính. | I42: Chưa kiểm tra | J42: Chưa có link video cuối. Quay, encode và upload vào clips/.
A43: MC38 | B43: Khác | C43: SB05 | D43: Võ Hoàng Danh | E43: File text nộp LMS đúng tên, nội dung là link Drive public. | F43: TODO_LMS_SUBMISSION_TXT_FILE_PATH | G43: 46216 | H43: Kiểm tra tên mã-nhóm_mssv1_mssv2_mssv3_mssv4.txt và nội dung chỉ chứa link Drive. | I43: Chưa kiểm tra | J43: Tạo file text sau khi chốt link Drive public.
A46: B. KIỂM TRA CẤU TRÚC GOOGLE DRIVE TRƯỚC KHI NỘP
A47: STT | B47: Hạng mục cần có | C47: Tên thư mục/file chuẩn | D47: Link trực tiếp | E47: Public? | F47: Mở được? | G47: Đủ nội dung? | H47: Người kiểm tra | I47: Ngày kiểm tra | J47: Ghi chú
...

Sheet 07_ChuanBiVanDap
A1: CHUẨN BỊ VẤN ĐÁP THEO YÊU CẦU TICKETBOX
A3: Giảng viên có thể hỏi bất kỳ thành viên nào. Hãy ghi ngắn gọn cách nhóm đã làm, file/code cần mở và người chịu trách nhiệm giải thích.
A5: STT | B5: Requirement ID | C5: Chủ đề vấn đáp | D5: Câu hỏi gợi ý | E5: Code/tài liệu cần mở | F5: Thành viên phụ trách | G5: Câu trả lời chuẩn bị ngắn gọn | H5: Đã luyện?
A6: 1 | B6: BP01 | C6: Kiến trúc | D6: Vì sao nhóm chọn kiến trúc này? Khi payment lỗi thì phần nào vẫn hoạt động? | E6: blueprint/01-system-design.md blueprint/03-high-level-architecture.md | F6: Huỳnh Thái Toàn | G6: Nhóm chọn NestJS modular monolith theo domain để transaction và triển khai demo đơn giản nhưng vẫn tách rõ module. Payment lỗi chỉ làm order ở pending_payment/pending_reconciliation; catalog, admin và scanner vẫn hoạt động, chưa phát hành vé trùng. | H6: Có
A7: 2 | B7: BP03 | C7: C4 Container | D7: Các container giao tiếp đồng bộ/bất đồng bộ như thế nào? Vì sao cần broker/cache? | E7: blueprint/02-c4-diagrams.md blueprint/05-business-flows.md | F7: Huỳnh Thái Toàn | G7: Web/PWA gọi Backend API đồng bộ qua REST. Tác vụ chậm dùng bản ghi bền vững trong PostgreSQL và scheduled worker; Redis chỉ cache/rate limit. Bản demo chưa dùng broker ngoài, nên durable table/outbox giữ trạng thái để retry. | H7: Có
A8: 3 | B8: BP05 | C8: Database | D8: Entity và transaction boundary nào đảm bảo không oversell? SQL/NoSQL được chọn vì sao? | E8: blueprint/04-database-design.md src/backend-api/prisma/schema.prisma src/backend-api/src/modules/inventory/inventory.repository.ts | F8: Võ Hoàng Danh | G8: PostgreSQL là source of truth vì inventory, quota, order và payment cần consistency mạnh. Khi reserve, Prisma transaction khóa inventory_counters và user_ticket_quotas bằng FOR UPDATE, kiểm tra tồn/quota rồi mới tăng reservedCount; NoSQL không phù hợp invariant này. | H8: Có
A9: 4 | B9: BP09/IM06 | C9: RBAC | D9: Một nhân sự soát vé thử gọi API tạo concert sẽ bị chặn ở đâu? | E9: blueprint/06-access-control.md src/backend-api/src/modules/auth/roles.guard.ts src/backend-api/src/modules/admin/admin.controller.ts | F9: Võ Hoàng Danh | G9: AuthGuard xác thực JWT trước, sau đó RolesGuard đối chiếu @Roles('organizer') trên AdminController. Tài khoản scanner bị trả 403 trước khi vào createConcert; AdminService còn kiểm tra organization ownership cho tài nguyên cụ thể. | H9: Có
A10: 5 | B10: BP10/IM12 | C10: Rate limiting | D10: Nhóm dùng thuật toán nào, key là user/IP/token nào, ngưỡng bao nhiêu và vì sao? | E10: blueprint/07-protection-mechanisms.md src/backend-api/src/common/cache/rate-limit.guard.ts src/backend-api/src/modules/inventory/inventory.controller.ts | F10: Nguyễn Hữu Phúc | G10: POST /reservations dùng fixed-window 60 giây trên Redis: IP 30, user 10, device/session 20. Key gồm scope + định danh + endpoint + cửa sổ; vượt ngưỡng trả 429 và Retry-After. Nhiều scope vừa hạn chế bot vừa không khóa nhầm toàn bộ người dùng chung IP. | H10: Có
A11: 6 | B11: BP11/IM13 | C11: Circuit breaker | D11: Điều kiện chuyển Closed → Open → Half-Open? Fallback khi payment lỗi là gì? | E11: blueprint/core-design-decisions/unstable-payment-gateway.md src/backend-api/src/modules/payment/resilience/payment-circuit-breaker.service.ts payment-circuit-breaker.service.spec.ts | F11: Huỳnh Thái Toàn | G11: Mặc định 5 lỗi retryable mở circuit; sau 30 giây chuyển Half-Open và chỉ cho một probe. Probe thành công về Closed, thất bại mở lại. Circuit mở trả 503 + Retry-After; timeout mơ hồ chuyển payment sang pending_reconciliation, không tạo intent mới. | H11: Có
A12: 7 | B12: BP12/IM14 | C12: Idempotency | D12: Nếu client retry 5 lần cùng Idempotency-Key, database và response thay đổi thế nào? | E12: src/backend-api/src/common/idempotency/idempotency.service.ts src/backend-api/src/modules/payment/payment-intent.service.ts src/backend-api/test/checkout-flow.e2e-spec.ts | F12: Huỳnh Thái Toàn | G12: Khóa được lưu duy nhất theo user + endpoint + Idempotency-Key kèm request hash. Lần đầu xử lý và lưu status/body; 4 lần sau replay đúng response, không thêm payment hay gọi provider lại. Cùng khóa nhưng body khác trả 409. | H12: Có
A13: 8 | B13: BP13/IM15 | C13: Caching | D13: TTL thông tin concert và số vé khác nhau ra sao? Khi bán thành công invalidate thế nào? | E13: src/backend-api/src/common/cache/cache.service.ts src/backend-api/src/common/cache/cache-invalidation.service.ts src/backend-api/src/common/cache/cache.service.spec.ts | F13: Nguyễn Hữu Phúc | G13: Concert list/detail mặc định TTL 60 giây, inventory summary 5 giây, có jitter 15%. Admin cập nhật, reservation thay đổi/hết hạn và payment thành công sẽ xóa key liên quan. Inventory cache chỉ để hiển thị; quyết định bán vẫn đọc PostgreSQL trong transaction. | H13: Có
A14: 9 | B14: IM03 | C14: Giới hạn vé/user | D14: Hai request đồng thời từ cùng tài khoản có thể vượt limit không? Test chứng minh? | E14: src/backend-api/src/modules/inventory/inventory.repository.ts src/backend-api/test/checkout-flow.e2e-spec.ts — concurrent quota test | F14: Võ Hoàng Danh | G14: Không. Cả hai request phải khóa cùng dòng user_ticket_quotas trong transaction; code tính paidCount + reservedCount + quantity rồi so với perUserLimit. Test concurrent reservation trong checkout-flow.e2e-spec.ts chứng minh tổng vé không vượt quota. | H14: Có
A15: 10 | B15: IM11 | C15: Tranh chấp vé | D15: Hai người mua vé cuối cùng cùng lúc: code nào quyết định người thắng? | E15: src/backend-api/src/modules/inventory/inventory.repository.ts src/backend-api/test/checkout-flow.e2e-spec.ts — last-ticket contention | F15: Nguyễn Minh Tú | G15: inventory.repository.ts khóa dòng inventory_counters bằng SELECT ... FOR UPDATE. Request vào trước thấy còn 1 vé, tạo reservation và tăng reservedCount; request sau đọc lại availableQuantity = 0 và nhận 409 sold_out. Test last-ticket contention chạy hai request song song để xác nhận. | H15: Có
A16: 11 | B16: IM08 | C16: Offline check-in | D16: Hai thiết bị offline quét cùng QR thì xử lý xung đột khi đồng bộ thế nào? | E16: src/backend-api/src/modules/scanner/scanner.repository.ts src/backend-api/test/scanner-check-in-sync.e2e-spec.ts src/scanner-pwa/src/lib/scanner/state.tsx | F16: Nguyễn Minh Tú | G16: Mỗi lần quét được lưu offline với clientEventId UUID rồi đẩy batch khi có mạng. Backend dùng serializable transaction và advisory lock theo eventId + ticketRef: bản ghi đầu accepted, bản ghi sau conflict/ticket_already_checked_in; retry cùng clientEventId chỉ replay kết quả cũ. | H16: Có
A17: 12 | B17: IM09 | C17: AI Artist Bio | D17: Pipeline đọc PDF, làm sạch, prompt/model và xử lý PDF lỗi/hallucination thế nào? | E17: src/backend-api/src/modules/artist-bio/artist-bio-processor.service.ts artist-bio-pdf.util.ts; artist-bio.module.ts artist-bio-processor.service.spec.ts | F17: Võ Hoàng Danh | G17: PDF được lưu rồi tạo durable job; worker extract text, sanitize và từ chối nếu dưới 40 ký tự. Có API key thì dùng Gemini 2.5 Flash, thiếu/lỗi thì fallback mock; lưu model/prompt version và chỉ tạo draft để organizer review/publish, nên AI không tự ghi đè nội dung công khai. | H17: Có
... A21: 16 | B21: SB01-SB05 | C21: Nộp bài | D21: Mở Drive ở chế độ ẩn danh; chỉ ra Blueprint, src/data/README và clips. | E21: [BỔ SUNG] Link Google Drive public blueprint/; src/; README.md [BỔ SUNG] data/; clips/; file mã-nhóm_mssv....txt | F21: Nguyễn Minh Tú | G21: Mở link Drive bằng cửa sổ ẩn danh và kiểm tra quyền xem. Chỉ lần lượt blueprint/, từng thư mục src/*, README và clips/video demo; đối chiếu checklist SB01-SB05. Nếu data hoặc clips chưa có trong gói nộp thì bổ sung trước hạn và kiểm tra lại link. | H21: Có

Sheet 08_TongHopGV
A1: TỔNG HỢP ĐÓNG GÓP CÁ NHÂN — PHỤC VỤ GIẢNG VIÊN VẤN ĐÁP
A3: Không sửa các ô màu xám. Phần bên dưới hiển thị rõ % hoàn thành đồ án theo checklist. Điểm/hệ số cá nhân chỉ là tín hiệu tham khảo; giảng viên quyết định sau khi kiểm tra minh chứng và vấn đáp.
A5: STT | B5: Thành viên | C5: MSSV | D5: Số task | E5: Task chính | F5: Điểm công việc | G5: Tỷ trọng task | H5: Tự ĐG TB | I5: ĐG chéo TB | J5: Số minh chứng | K5: Yêu cầu làm owner | L5: Hệ số tham khảo | M5: Cảnh báo
A6: 1 | B6: =IF('01_ThongTinNhom'!B16="","",'01_ThongTinNhom'!B16) -> Nguyễn Minh Tú | C6: =IF('01_ThongTinNhom'!C16="","",'01_ThongTinNhom'!C16) -> 23120101 | D6: =IF(B6="","",COUNTIF('03_PhanCongTask'!$F$6:$F$38,B6)) -> 8 | E6: =IF(B6="","",COUNTIFS('03_PhanCongTask'!$F$6:$F$38,B6,'03_PhanCongTask'!$I$6:$I$38,"Chính")) -> 8 | F6: =IF(B6="","",SUMIF('03_PhanCongTask'!$F$6:$F$38,B6,'03_PhanCongTask'!$N$6:$N$38)) -> 41.52 | G6: =IF(B6="","",IF(SUM($F$6:$F$9)=0,0,F6/SUM($F$6:$F$9))) -> 0.24636563 | H6: =IF(B6="","",IFERROR(AVERAGEIF('04_TuDanhGia'!$B$6:$B$9,B6,'04_TuDanhGia'!$L$6:$L$9),0)) -> 4.56 | I6: =IF(B6="","",IFERROR(AVERAGEIF('05_DanhGiaCheo'!$C$6:$C$17,B6,'05_DanhGiaCheo'!$J$6:$J$17),0)) -> 4.83 | J6: =IF(B6="","",COUNTIF('06_MinhChung_NopBai'!$D$6:$D$43,B6)) -> 7 | K6: =IF(B6="","",COUNTIF('02_ChecklistYeuCau'!$F$6:$F$43,B6)) -> 9 | L6: =IF(B6="","",IF(SUM($F$6:$F$9)=0,0,MIN(1.3,MAX(0.7,0.65*(G6/(1/MAX(1,COUNTIF('01_ThongTinNhom'!$B$16:$B$19,"<>"))))+0.2*(I6/5)+0.15*(H6/5))))) -> 0.97055064 | M6: =IF(B6="","",IF(D6=0,"Chưa khai task; ","")&IF(J6=0,"Chưa có minh chứng; ","")&IF(K6=0,"Chưa là owner yêu cầu; ","")&IF(AND(G6>0,G6<0.15),"Tỷ trọng task thấp; ","")&IF(I6=0,"Chưa được đánh giá chéo; ",""))
A7: 2 | B7: =IF('01_ThongTinNhom'!B17="","",'01_ThongTinNhom'!B17) -> Võ Hoàng Danh | C7: =IF('01_ThongTinNhom'!C17="","",'01_ThongTinNhom'!C17) -> 23120117 | D7: =IF(B7="","",COUNTIF('03_PhanCongTask'!$F$6:$F$38,B7)) -> 7 | E7: =IF(B7="","",COUNTIFS('03_PhanCongTask'!$F$6:$F$38,B7,'03_PhanCongTask'!$I$6:$I$38,"Chính")) -> 7 | F7: =IF(B7="","",SUMIF('03_PhanCongTask'!$F$6:$F$38,B7,'03_PhanCongTask'!$N$6:$N$38)) -> 31.73 | G7: =IF(B7="","",IF(SUM($F$6:$F$9)=0,0,F7/SUM($F$6:$F$9))) -> 0.18827508 | H7: =IF(B7="","",IFERROR(AVERAGEIF('04_TuDanhGia'!$B$6:$B$9,B7,'04_TuDanhGia'!$L$6:$L$9),0)) -> 4.67 | I7: =IF(B7="","",IFERROR(AVERAGEIF('05_DanhGiaCheo'!$C$6:$C$17,B7,'05_DanhGiaCheo'!$J$6:$J$17),0)) -> 4.7766667 | J7: =IF(B7="","",COUNTIF('06_MinhChung_NopBai'!$D$6:$D$43,B7)) -> 11 | K7: =IF(B7="","",COUNTIF('02_ChecklistYeuCau'!$F$6:$F$43,B7)) -> 11 | L7: =IF(B7="","",IF(SUM($F$6:$F$9)=0,0,MIN(1.3,MAX(0.7,0.65*(G7/(1/MAX(1,COUNTIF('01_ThongTinNhom'!$B$16:$B$19,"<>"))))+0.2*(I7/5)+0.15*(H7/5))))) -> 0.82068189 | M7: =IF(B7="","",IF(D7=0,"Chưa khai task; ","")&IF(J7=0,"Chưa có minh chứng; ","")&IF(K7=0,"Chưa là owner yêu cầu; ","")&IF(AND(G7>0,G7<0.15),"Tỷ trọng task thấp; ","")&IF(I7=0,"Chưa được đánh giá chéo; ",""))
A8: 3 | B8: =IF('01_ThongTinNhom'!B18="","",'01_ThongTinNhom'!B18) -> Nguyễn Hữu Phúc | C8: =IF('01_ThongTinNhom'!C18="","",'01_ThongTinNhom'!C18) -> 23120157 | D8: =IF(B8="","",COUNTIF('03_PhanCongTask'!$F$6:$F$38,B8)) -> 9 | E8: =IF(B8="","",COUNTIFS('03_PhanCongTask'!$F$6:$F$38,B8,'03_PhanCongTask'!$I$6:$I$38,"Chính")) -> 9 | F8: =IF(B8="","",SUMIF('03_PhanCongTask'!$F$6:$F$38,B8,'03_PhanCongTask'!$N$6:$N$38)) -> 46.08 | G8: =IF(B8="","",IF(SUM($F$6:$F$9)=0,0,F8/SUM($F$6:$F$9))) -> 0.27342313 | H8: =IF(B8="","",IFERROR(AVERAGEIF('04_TuDanhGia'!$B$6:$B$9,B8,'04_TuDanhGia'!$L$6:$L$9),0)) -> 4.78 | I8: =IF(B8="","",IFERROR(AVERAGEIF('05_DanhGiaCheo'!$C$6:$C$17,B8,'05_DanhGiaCheo'!$J$6:$J$17),0)) -> 4.83 | J8: =IF(B8="","",COUNTIF('06_MinhChung_NopBai'!$D$6:$D$43,B8)) -> 10 | K8: =IF(B8="","",COUNTIF('02_ChecklistYeuCau'!$F$6:$F$43,B8)) -> 10 | L8: =IF(B8="","",IF(SUM($F$6:$F$9)=0,0,MIN(1.3,MAX(0.7,0.65*(G8/(1/MAX(1,COUNTIF('01_ThongTinNhom'!$B$16:$B$19,"<>"))))+0.2*(I8/5)+0.15*(H8/5))))) -> 1.0475001 | M8: =IF(B8="","",IF(D8=0,"Chưa khai task; ","")&IF(J8=0,"Chưa có minh chứng; ","")&IF(K8=0,"Chưa là owner yêu cầu; ","")&IF(AND(G8>0,G8<0.15),"Tỷ trọng task thấp; ","")&IF(I8=0,"Chưa được đánh giá chéo; ",""))
A9: 4 | B9: =IF('01_ThongTinNhom'!B19="","",'01_ThongTinNhom'!B19) -> Huỳnh Thái Toàn | C9: =IF('01_ThongTinNhom'!C19="","",'01_ThongTinNhom'!C19) -> 23120175 | D9: =IF(B9="","",COUNTIF('03_PhanCongTask'!$F$6:$F$38,B9)) -> 9 | E9: =IF(B9="","",COUNTIFS('03_PhanCongTask'!$F$6:$F$38,B9,'03_PhanCongTask'!$I$6:$I$38,"Chính")) -> 9 | F9: =IF(B9="","",SUMIF('03_PhanCongTask'!$F$6:$F$38,B9,'03_PhanCongTask'!$N$6:$N$38)) -> 49.2 | G9: =IF(B9="","",IF(SUM($F$6:$F$9)=0,0,F9/SUM($F$6:$F$9))) -> 0.29193615 | H9: =IF(B9="","",IFERROR(AVERAGEIF('04_TuDanhGia'!$B$6:$B$9,B9,'04_TuDanhGia'!$L$6:$L$9),0)) -> 4.89 | I9: =IF(B9="","",IFERROR(AVERAGEIF('05_DanhGiaCheo'!$C$6:$C$17,B9,'05_DanhGiaCheo'!$J$6:$J$17),0)) -> 4.83 | J9: =IF(B9="","",COUNTIF('06_MinhChung_NopBai'!$D$6:$D$43,B9)) -> 10 | K9: =IF(B9="","",COUNTIF('02_ChecklistYeuCau'!$F$6:$F$43,B9)) -> 8 | L9: =IF(B9="","",IF(SUM($F$6:$F$9)=0,0,MIN(1.3,MAX(0.7,0.65*(G9/(1/MAX(1,COUNTIF('01_ThongTinNhom'!$B$16:$B$19,"<>"))))+0.2*(I9/5)+0.15*(H9/5))))) -> 1.098934 | M9: =IF(B9="","",IF(D9=0,"Chưa khai task; ","")&IF(J9=0,"Chưa có minh chứng; ","")&IF(K9=0,"Chưa là owner yêu cầu; ","")&IF(AND(G9>0,G9<0.15),"Tỷ trọng task thấp; ","")&IF(I9=0,"Chưa được đánh giá chéo; ",""))
A12: TIẾN ĐỘ ĐỒ ÁN
A13: TIẾN ĐỘ TỰ KHAI BÁO | D13: HOÀN THÀNH ĐỦ MINH CHỨNG
A14: =IFERROR(SUMIFS('02_ChecklistYeuCau'!$H$6:$H$43,'02_ChecklistYeuCau'!$G$6:$G$43,"<>Không áp dụng")/COUNTIFS('02_ChecklistYeuCau'!$A$6:$A$43,"<>",'02_ChecklistYeuCau'!$G$6:$G$43,"<>Không áp dụng")/100,0) -> 0.85789474 | D14: =IFERROR(COUNTIFS('02_ChecklistYeuCau'!$G$6:$G$43,"Hoàn thành",'02_ChecklistYeuCau'!$J$6:$J$43,"Đạt",'02_ChecklistYeuCau'!$I$6:$I$43,"<>")/COUNTIFS('02_ChecklistYeuCau'!$A$6:$A$43,"<>",'02_ChecklistYeuCau'!$G$6:$G$43,"<>Không áp dụng"),0) -> 0.68421053
A18: Chỉ số | B18: Kết quả | C18: Cách tính/ý nghĩa
A19: Tổng yêu cầu áp dụng | B19: =COUNTIFS('02_ChecklistYeuCau'!$A$6:$A$43,"<>",'02_ChecklistYeuCau'!$G$6:$G$43,"<>Không áp dụng") -> 38 | C19: Tổng số dòng yêu cầu, không tính mục được chọn “Không áp dụng”.
A20: Số yêu cầu hoàn thành 100% | B20: =COUNTIF('02_ChecklistYeuCau'!$G$6:$G$43,"Hoàn thành") -> 26 | C20: Số mục có trạng thái “Hoàn thành”.
A21: Tỷ lệ yêu cầu hoàn thành 100% | B21: =IFERROR(B20/B19,0) -> 0.68421053 | C21: Số mục “Hoàn thành” chia tổng yêu cầu áp dụng.
A22: Tỷ lệ tự kiểm tra đạt | B22: =IFERROR(COUNTIFS('02_ChecklistYeuCau'!$J$6:$J$43,"Đạt",'02_ChecklistYeuCau'!$G$6:$G$43,"<>Không áp dụng")/B19,0) -> 0.68421053 | C22: Số mục có kết quả tự kiểm tra “Đạt” chia tổng yêu cầu áp dụng.
A23: Tỷ lệ có minh chứng | B23: =IFERROR(COUNTIFS('02_ChecklistYeuCau'!$I$6:$I$43,"<>",'02_ChecklistYeuCau'!$G$6:$G$43,"<>Không áp dụng")/B19,0) -> 1 | C23: Số mục có link/path minh chứng chia tổng yêu cầu áp dụng.
A24: Tỷ lệ hoàn thành đủ minh chứng | B24: =D14 -> 0.68421053 | C24: Chỉ tính mục đồng thời: Hoàn thành + Đạt + có minh chứng.
A25: Số yêu cầu chưa hoàn thành | B25: =MAX(B19-B20,0) -> 12 | C25: Các yêu cầu áp dụng nhưng chưa có trạng thái “Hoàn thành”.
A26: Số mục không áp dụng | B26: =COUNTIF('02_ChecklistYeuCau'!$G$6:$G$43,"Không áp dụng") -> 0 | C26: Các mục được nhóm xác định không áp dụng; tự động loại khỏi mẫu số.
A28: Cách đọc: “Tiến độ tự khai báo” phản ánh mức hoàn thành trung bình do nhóm nhập ở cột % HT. Giảng viên nên ưu tiên “Hoàn thành đủ minh chứng” vì chỉ tính các yêu cầu đã hoàn thành, tự kiểm tra đạt và có minh chứng để mở khi vấn đáp.
